<?xml version="1.0" ?>
<sdf version="1.5">
  <world name="default">
    <scene>
      <grid>true</grid>
    </scene>
    <!-- A global light source -->
    <include>
      <uri>model://sun</uri>
    </include>

    <model name="Ice Rink">
      <link name="ice_link">
        <inertial>
          <inertia>
            <izz>2.825</izz>
            <iyz>0.0</iyz>
            <iyy>3.6250000000000004</iyy>
            <ixx>3.25</ixx>
            <ixy>0.0</ixy>
            <ixz>0.0</ixz>
            <gravity>1</gravity>
          </inertia>
          <mass>30000.0</mass>
          <pose>0 0 0 0 0 0</pose>
        </inertial>

        <collision name="collision">
          <static>true</static>
          <pose>0 0 0 0 0 0</pose>
          <geometry>
            <mesh>
              <scale>0.001 0.001 0.001</scale>
              <uri>model://ice_rink/meshes/Ice.stl</uri>
            </mesh>
          </geometry>
          <surface>
            <friction>
              <ode>
                <mu>100</mu>
                <mu2>50</mu2>
              </ode>
            </friction>
          </surface>
        </collision>

        <visual name="visual">
          <pose>0 0 0 0 0 0</pose>
          <material>
            <ambient>1 1 1 1</ambient>
            <diffuse>1 1 1 1</diffuse>
            <specular>0.1 0.1 0.1 1</specular>
            <emissive>0 0 0 0</emissive>
          </material>
        <geometry>
            <mesh>
              <scale>0.001 0.001 0.001</scale>
              <uri>model://ice_rink/meshes/Ice.stl</uri>
            </mesh>
          </geometry>
        </visual>

        <self_collide>1</self_collide>
      </link>

      <link name="red_line_link">
        <inertial>
          <inertia>
            <izz>2.825</izz>
            <iyz>0.0</iyz>
            <iyy>3.6250000000000004</iyy>
            <ixx>3.25</ixx>
            <ixy>0.0</ixy>
            <ixz>0.0</ixz>
            <gravity>1</gravity>
          </inertia>
          <mass>30000.0</mass>
          <pose>0 0 0 0 0 0</pose>
        </inertial>

        <collision name="collision">
          <static>true</static>
          <pose>0 0 0 0 0 0</pose>
          <geometry>
            <mesh>
              <scale>0.001 0.001 0.001</scale>
              <uri>model://ice_rink/meshes/Red_Line.stl</uri>
            </mesh>
          </geometry>
          <surface>
            <friction>
              <ode>
                <mu>100</mu>
                <mu2>50</mu2>
              </ode>
            </friction>
          </surface>
        </collision>

        <visual name="visual">
          <pose>0 0 0 0 0 0</pose>
          <material>
            <ambient>1 0 0 1</ambient>
            <diffuse>1 0 0 1</diffuse>
            <specular>0.1 0.1 0.1 1</specular>
            <emissive>0 0 0 0</emissive>
          </material>
        <geometry>
            <mesh>
              <scale>0.001 0.001 0.001</scale>
              <uri>model://ice_rink/meshes/Red_Line.stl</uri>
            </mesh>
          </geometry>
        </visual>

        <self_collide>1</self_collide>
      </link>

      <link name="blue_line_link">
        <inertial>
          <inertia>
            <izz>2.825</izz>
            <iyz>0.0</iyz>
            <iyy>3.6250000000000004</iyy>
            <ixx>3.25</ixx>
            <ixy>0.0</ixy>
            <ixz>0.0</ixz>
            <gravity>1</gravity>
          </inertia>
          <mass>30000.0</mass>
          <pose>0 0 0 0 0 0</pose>
        </inertial>

        <collision name="collision">
          <static>true</static>
          <pose>0 0 0 0 0 0</pose>
          <geometry>
            <mesh>
              <scale>0.001 0.001 0.001</scale>
              <uri>model://ice_rink/meshes/Blue_Line.stl</uri>
            </mesh>
          </geometry>
          <surface>
            <friction>
              <ode>
                <mu>100</mu>
                <mu2>50</mu2>
              </ode>
            </friction>
          </surface>
        </collision>

        <visual name="visual">
          <pose>0 0 0 0 0 0</pose>
          <material>
            <ambient>0 0 1 1</ambient>
            <diffuse>0 0 1 1</diffuse>
            <specular>0.1 0.1 0.1 1</specular>
            <emissive>0 0 0 0</emissive>
          </material>
        <geometry>
            <mesh>
              <scale>0.001 0.001 0.001</scale>
              <uri>model://ice_rink/meshes/Blue_Line.stl</uri>
            </mesh>
          </geometry>
        </visual>

        <self_collide>1</self_collide>
      </link>

      <self_collide>0</self_collide>
      <enable_wind>0</enable_wind>
      <kinematic>0</kinematic>
      <static>true</static>

      <link name="kick_plate_link">
        <inertial>
          <inertia>
            <izz>2.825</izz>
            <iyz>0.0</iyz>
            <iyy>3.6250000000000004</iyy>
            <ixx>3.25</ixx>
            <ixy>0.0</ixy>
            <ixz>0.0</ixz>
            <gravity>1</gravity>
          </inertia>
          <mass>30000.0</mass>
          <pose>0 0 0 0 0 0</pose>
        </inertial>

        <collision name="collision">
          <static>true</static>
          <pose>0 0 0 0 0 0</pose>
          <geometry>
            <mesh>
              <scale>0.001 0.001 0.001</scale>
              <uri>model://ice_rink/meshes/KickPlate.stl</uri>
            </mesh>
          </geometry>
          <surface>
            <friction>
              <ode>
                <mu>100</mu>
                <mu2>50</mu2>
              </ode>
            </friction>
          </surface>
        </collision>

        <visual name="visual">
          <pose>0 0 0 0 0 0</pose>
          <material>
            <ambient>1 1 0 1</ambient>
            <diffuse>1 1 0 1</diffuse>
            <specular>0.1 0.1 0.1 1</specular>
            <emissive>0 0 0 0</emissive>
          </material>
          <geometry>
            <mesh>
              <scale>0.001 0.001 0.001</scale>
              <uri>model://ice_rink/meshes/KickPlate.stl</uri>
            </mesh>
          </geometry>
        </visual>

        <self_collide>1</self_collide>
      </link>


      <link name="boards_link">
        <inertial>
          <inertia>
            <izz>2.825</izz>
            <iyz>0.0</iyz>
            <iyy>3.6250000000000004</iyy>
            <ixx>3.25</ixx>
            <ixy>0.0</ixy>
            <ixz>0.0</ixz>
            <gravity>1</gravity>
          </inertia>
          <mass>30000.0</mass>
          <pose>0 0 0 0 0 0</pose>
        </inertial>

        <collision name="collision">
          <static>true</static>
          <pose>0 0 0 0 0 0</pose>
          <geometry>
            <mesh>
              <scale>0.001 0.001 0.001</scale>
              <uri>model://ice_rink/meshes/Boards.stl</uri>
            </mesh>
          </geometry>
          <surface>
            <!-- <friction>
              <ode>
                <mu>100</mu>
                <mu2>50</mu2>
              </ode>
            </friction> -->
          </surface>
        </collision>

        <visual name="visual">
          <pose>0 0 0 0 0 0</pose>
          <material>
            <ambient>1 1 1 1</ambient>
            <diffuse>1 1 1 1</diffuse>
            <specular>0.1 0.1 0.1 1</specular>
            <emissive>0 0 0 0</emissive>
          </material>
          <geometry>
            <mesh>
              <scale>0.001 0.001 0.001</scale>
              <uri>model://ice_rink/meshes/Boards.stl</uri>
            </mesh>
          </geometry>
        </visual>

        <self_collide>1</self_collide>
      </link>

      <link name="hand_rail_link">
        <inertial>
          <inertia>
            <izz>2.825</izz>
            <iyz>0.0</iyz>
            <iyy>3.6250000000000004</iyy>
            <ixx>3.25</ixx>
            <ixy>0.0</ixy>
            <ixz>0.0</ixz>
            <gravity>1</gravity>
          </inertia>
          <mass>30000.0</mass>
          <pose>0 0 0 0 0 0</pose>
        </inertial>

        <collision name="collision">
          <static>true</static>
          <pose>0 0 0 0 0 0</pose>
          <geometry>
            <mesh>
              <scale>0.001 0.001 0.001</scale>
              <uri>model://ice_rink/meshes/HandRail.stl</uri>
            </mesh>
          </geometry>
          <surface>
            <!-- <friction>
              <ode>
                <mu>100</mu>
                <mu2>50</mu2>
              </ode>
            </friction> -->
          </surface>
        </collision>

        <visual name="visual">
          <pose>0 0 0 0 0 0</pose>
          <material>
            <ambient>0 0 1 1</ambient>
            <diffuse>0 0 1 1</diffuse>
            <specular>0.1 0.1 0.1 1</specular>
            <emissive>0 0 0 0</emissive>
          </material>
          <geometry>
            <mesh>
              <scale>0.001 0.001 0.001</scale>
              <uri>model://ice_rink/meshes/HandRail.stl</uri>
            </mesh>
          </geometry>
        </visual>

        <self_collide>1</self_collide>
      </link>
    </model>


    <model name="zamboni">
      <pose>0 0 0.75 0 0 0</pose>

      <link name='base_link' />

      <joint name='chassis_link_joint' type='fixed'>
        <pose>0.0 0.0 0.0 0 0 0</pose>
        <parent>base_link</parent>
        <child>chassis_link</child>
      </joint>

      <joint name="realsense_joint" type="fixed">
        <parent>base_link</parent>
        <child>depth_link</child>
        <pose>0 0 0 0 0 0</pose>
        <axis>
          <xyz>0 0 1</xyz>
        </axis>
      </joint>

      <link name="depth_link">
        <pose relative_to='base_link'>0 2.34 0.72 0 0 0</pose>
        <inertial>
          <mass>0.1</mass>
        </inertial>

        <visual name="camera_visual">
          <pose relative_to='base_link'>0 2.34 0.72 0 0 0</pose>
          <geometry>
            <box>
              <size>0.015 0.08 0.022</size>
            </box>
          </geometry>
          <material>
            <ambient>0 0 0 1.0</ambient>
            <diffuse>0 0 0 1.0</diffuse>
            <specular>0.0 0.0 0.0 1.0</specular>
            <emissive>0.0 0.0 0.0 1.0</emissive>
          </material>
        </visual>

        <sensor name="depth_camera" type="depth">
          <pose relative_to='base_link'>0 2.34 0.72 0 0 1.5708</pose>
          
          <always_on>1</always_on>
          <visualize>true</visualize>
          <update_rate>15</update_rate>
          <camera name="depth_camera">
            <horizontal_fov>1.11701</horizontal_fov><!--69.4 deg = 1.211258501 rad -->
            <aspect_ratio>0.715585</aspect_ratio><!-- 16:9-->
            <image>
                <width>640</width>
                <height>480</height>
                <format>B8G8R8</format>
            </image>
            <clip>
                <near>0.1</near>
                <far>16</far>
            </clip>
            <noise>
                <type>gaussian</type>
                <mean>0.0</mean>
                <stddev>0.007</stddev>
            </noise>
          </camera>
          <plugin name="camera_plugin" filename="libgazebo_ros_camera.so">
            <camera_name>depth_camera</camera_name>
            <frame_name>realsense_link</frame_name>
            <hack_baseline>0</hack_baseline>
            <max_depth>16.0</max_depth>
            <min_depth>0.001</min_depth>
          </plugin>
        </sensor>

        <sensor name="normal_camera" type="camera">
          <pose relative_to='base_link'>0 2.34 0.72 0 0 1.5708</pose>
          
          <!-- <always_on>1</always_on> -->
          <visualize>true</visualize>
          <update_rate>15</update_rate>
          <camera name="normal_camera">
            <horizontal_fov>1.11701</horizontal_fov><!--69.4 deg = 1.211258501 rad -->
            <aspect_ratio>0.715585</aspect_ratio><!-- 16:9-->
            <image>
                <width>640</width>
                <height>480</height>
                <format>RGB_INT8</format>
            </image>
            <clip>
                <near>0.1</near>
                <far>20</far>
            </clip>
          </camera>
          <plugin name="camera_plugin" filename="libgazebo_ros_camera.so">
            <!-- <camera_name>normal_camera</camera_name> -->
            <frame_name>normal_camera_frame</frame_name>
          </plugin>
        </sensor>
      </link>

      <joint name="imu_joint" type="fixed">
        <parent>base_link</parent>
        <child>imu_link</child>
        <pose>0 0 0 0 0 0</pose>
        <axis>
          <xyz>0 0 1</xyz>
        </axis>
      </joint>

      <link name="imu_link">
        <pose relative_to='base_link'>0 0 0.72 0 0 0</pose>
        <inertial>
          <mass>0.1</mass>
        </inertial>

        <visual name="imu_visual">
          <pose relative_to='base_link'>0 0 0.72 0 0 0</pose>
          <geometry>
            <box>
              <size>0.015 0.08 0.022</size>
            </box>
          </geometry>
          <material>
            <ambient>0 0 0 1.0</ambient>
            <diffuse>0 0 0 1.0</diffuse>
            <specular>0.0 0.0 0.0 1.0</specular>
            <emissive>0.0 0.0 0.0 1.0</emissive>
          </material>
        </visual>

        <sensor name="imu_sensor" type="imu">
          <pose relative_to='base_link'>0 0 0.72 0 0 1.5708</pose>
          <always_on>true</always_on>
          <update_rate>100</update_rate>
          <imu>
            <angular_velocity>
              <x>
                <noise type="gaussian">
                  <mean>0.0</mean>
                  <stddev>2e-4</stddev>
                </noise>
              </x>
              <y>
                <noise type="gaussian">
                  <mean>0.0</mean>
                  <stddev>2e-4</stddev>
                </noise>
              </y>
              <z>
                <noise type="gaussian">
                  <mean>0.0</mean>
                  <stddev>2e-4</stddev>
                </noise>
              </z>
            </angular_velocity>
            <linear_acceleration>
              <x>
                <noise type="gaussian">
                  <mean>0.0</mean>
                  <stddev>1.7e-2</stddev>
                </noise>
              </x>
              <y>
                <noise type="gaussian">
                  <mean>0.0</mean>
                  <stddev>1.7e-2</stddev>
                </noise>
              </y>
              <z>
                <noise type="gaussian">
                  <mean>0.0</mean>
                  <stddev>1.7e-2</stddev>
                </noise>
              </z>
            </linear_acceleration>
          </imu>
          <plugin name="bytes_imu" filename="libgazebo_ros_imu_sensor.so">
              <ros>
                  <namespace>imu</namespace>
                  <remapping>~/out:=data</remapping>
              </ros>
              <initial_orientation_as_reference>false</initial_orientation_as_reference>
          </plugin>
        </sensor>
      </link>

      <link name='chassis_link'>
        <inertial>
          <pose>0 0.73 0.30 0 -0 0</pose>
          <mass>1326.0</mass>
          <inertia>
            <ixx>2581.13354740</ixx>
            <ixy>0</ixy>
            <ixz>0</ixz>
            <iyy>591.30846112</iyy>
            <iyz>0</iyz>
            <izz>2681.95008628</izz>
          </inertia>
        </inertial>
        <collision name='chassis_link_fixed_joint_lump__chassis_link_collision'>
          <pose>0 0 0 0 0 0</pose>
          <geometry>
            <mesh>
              <scale>0.001 0.001 0.001</scale>
              <uri>model://zamboni/meshes/zamboni_no_cond.stl</uri>
            </mesh>
          </geometry>
          <surface>
            <contact>
              <ode />
            </contact>
            <friction>
              <ode>
                <mu>0.2</mu>
                <mu2>0.2</mu2>
              </ode>
            </friction>
          </surface>
        </collision>

        <visual name='chassis_link_fixed_joint_lump__chassis_link_visual'>
          <pose>0 0 0 0 0 0</pose>
          <geometry>
            <mesh>
              <scale>0.001 0.001 0.001</scale>
              <uri>model://zamboni/meshes/zamboni_no_cond.stl</uri>
            </mesh>
          </geometry>
        </visual>
        <self_collide>1</self_collide>
      </link>

      <joint name='bl_axle' type='revolute'>
        <pose relative_to='chassis_link'>-0.74 0 0 0 -0 0</pose>
        <parent>chassis_link</parent>
        <child>bl_1</child>
        <axis>
          <xyz>-1 0 0</xyz>
          <dynamics>
            <!-- <friction>12.031606150200002</friction> -->
            <spring_stiffness>20.0</spring_stiffness>
            <damping>20.0</damping>
          </dynamics>
        </axis>
      </joint>

      <joint name='br_axle' type='revolute'>
        <pose relative_to='chassis_link'>0.74 0 0 0 -0 0</pose>
        <parent>chassis_link</parent>
        <child>br_1</child>
        <axis>
          <xyz>-1 0 0</xyz>
          <dynamics>
            <!-- <friction>12.031606150200002</friction> -->
            <spring_stiffness>20.0</spring_stiffness>
            <damping>20.0</damping>
          </dynamics>
        </axis>
      </joint>

      <joint name='fl_axle' type='revolute'>
        <pose relative_to='l_steer_1'>0 0 0 0 -0 0</pose>
        <parent>l_steer_1</parent>
        <child>fl_1</child>
        <axis>
          <xyz>-1 0 0</xyz>
          <dynamics>
            <friction>12.031606150200002</friction>
          </dynamics>
        </axis>
      </joint>

      <joint name='fr_axle' type='revolute'>
        <pose relative_to='r_steer_1'>0 0 0 0 -0 0</pose>
        <parent>r_steer_1</parent>
        <child>fr_1</child>
        <axis>
          <xyz>-1 0 0</xyz>
          <dynamics>
            <friction>12.031606150200002</friction>
          </dynamics>
        </axis>
      </joint>

      <joint name='l_steer' type='revolute'>
        <pose relative_to='chassis_link'>-0.74 1.70 0 0 -0 0</pose>
        <parent>chassis_link</parent>
        <child>l_steer_1</child>
        <axis>
          <xyz>0 0 1</xyz>
          <limit>
            <lower>-0.95</lower>
            <upper>0.95</upper>
          </limit>
          <dynamics>
              <damping>0.01</damping>
            <friction>18.0474092253</friction>
          </dynamics>
        </axis>
      </joint>

      <joint name='r_steer' type='revolute'>
        <pose relative_to='chassis_link'>0.74 1.70 0 0 -0 0</pose>
        <parent>chassis_link</parent>
        <child>r_steer_1</child>
        <axis>
          <xyz>0 0 1</xyz>
          <limit>
            <lower>-0.95</lower>
            <upper>0.95</upper>
          </limit>
          <dynamics>
            <damping>0.01</damping>
            <friction>18.0474092253</friction>
          </dynamics>
        </axis>
      </joint>

      <link name='bl_1'>
        <pose relative_to='bl_axle'>0 0 0 0 0 0</pose>
        <inertial>
          <pose>-0.0377 0 -0 0 -0 0</pose>
          <mass>24.5</mass>
          <inertia>
            <ixx>1.84514</ixx>
            <ixy>0</ixy>
            <ixz>0</ixz>
            <iyy>1.04961</iyy>
            <iyz>0</iyz>
            <izz>1.04961</izz>
          </inertia>
        </inertial>
        <collision name='bl_1_collision'>
          <pose relative_to='bl_axle'>0.05 0 0 0 1.5708 0</pose>
          <geometry>
            <cylinder>
              <radius>.28</radius>
              <length>.22</length>
            </cylinder>
          </geometry>
          <surface>
            <!-- <contact>
              <ode />
            </contact> -->
            <contact>
              <ode>
                <min_depth>0.001</min_depth>
                <kp>1e9</kp>
              </ode>
            </contact>
            <friction>
              <ode>
                <mu>1.1</mu>
                <mu2>1.1</mu2>
                <slip1>0.0</slip1>
                <slip2>0.0</slip2>
              </ode>
            </friction>
          </surface>
        </collision>
        <visual name='bl_1_visual'>
          <pose>0.770 0.891968 0.132 0 -0 0</pose>
          <geometry>
            <mesh>
              <scale>0.00088 0.00088 0.00088</scale>
              <uri>model://zamboni/meshes/bl_1.stl</uri>
            </mesh>
          </geometry>
        </visual>
        <self_collide>1</self_collide>
      </link>

      <link name='br_1'>
        <pose relative_to='br_axle'>0 0 0 0 -0 0</pose>
        <inertial>
          <pose>-0.0377 0 -0 0 -0 0</pose>
          <mass>24.5</mass>
          <inertia>
            <ixx>1.84514</ixx>
            <ixy>0</ixy>
            <ixz>0</ixz>
            <iyy>1.04961</iyy>
            <iyz>0</iyz>
            <izz>1.04961</izz>
          </inertia>
        </inertial>
        <collision name='br_1_collision'>
          <pose relative_to='br_axle'>-0.05 0 0 0 1.5708 0</pose>
          <geometry>
            <cylinder>
              <radius>.28</radius>
              <length>.23</length>
            </cylinder>
          </geometry>
          <surface>
            <!-- <contact>
              <ode />
            </contact> -->
            <contact>
              <ode>
                <min_depth>0.001</min_depth>
                <kp>1e9</kp>
              </ode>
            </contact>
            <friction>
              <ode>
                <mu>1.1</mu>
                <mu2>1.1</mu2>
                <slip1>0.0</slip1>
                <slip2>0.0</slip2>
              </ode>
            </friction>
          </surface>
        </collision>
        <visual name='br_1_visual'>
          <pose>-0.770 0.891968 0.132 0 -0 0</pose>
          <geometry>
            <mesh>
              <scale>0.00088 0.00088 0.00088</scale>
              <uri>model://zamboni/meshes/br_1.stl</uri>
            </mesh>
          </geometry>
        </visual>
        <self_collide>1</self_collide>
      </link>

      <link name='fl_1'>
        <pose relative_to='fl_axle'>0 0 0 0 -0 0</pose>
        <inertial>
          <pose>-0.0377 0 -0 0 -0 0</pose>
          <mass>24.5</mass>
          <inertia>
            <ixx>1.84514</ixx>
            <ixy>0</ixy>
            <ixz>0</ixz>
            <iyy>1.04961</iyy>
            <iyz>0</iyz>
            <izz>1.04961</izz>
          </inertia>
        </inertial>
        <collision name='fl_1_collision'>
          <!-- <pose>0.7875 -1.3657 0.15 0 -0 0</pose> -->
          <pose relative_to='fl_axle'>0.05 0 0 0 1.5708 0</pose>
          <geometry>
            <cylinder>
              <radius>.28</radius>
              <length>.22</length>
            </cylinder>
          </geometry>
          <!-- <geometry>
            <mesh>
              <scale>0.00088 0.00088 0.00088</scale>
              <uri>model://zamboni/meshes/fl_1.stl</uri>
            </mesh>
          </geometry> -->
          <surface>
            <!-- <contact>
              <ode />
            </contact> -->
            <contact>
              <ode>
                <min_depth>0.001</min_depth>
                <kp>1e9</kp>
              </ode>
            </contact>
            <friction>
              <ode>
                <mu>0.9</mu>
                <mu2>0.9</mu2>
                <slip1>0.0</slip1>
                <slip2>0.0</slip2>
              </ode>
            </friction>
          </surface>
        </collision>
        <visual name='fl_1_visual'>
          <pose>0.770 -1.33 0.132 0 -0 0</pose>
          <geometry>
            <mesh>
              <scale>0.00088 0.00088 0.00088</scale>
              <uri>model://zamboni/meshes/fl_1.stl</uri>
            </mesh>
          </geometry>
        </visual>
        <self_collide>1</self_collide>
      </link>

      <link name='fr_1'>
        <pose relative_to='fr_axle'>0 0 0 0 -0 0</pose>
        <inertial>
          <pose>-0.0377 0 -0 0 -0 0</pose>
          <mass>24.5</mass>
          <inertia>
            <ixx>1.84514</ixx>
            <ixy>0</ixy>
            <ixz>0</ixz>
            <iyy>1.04961</iyy>
            <iyz>0</iyz>
            <izz>1.04961</izz>
          </inertia>
        </inertial>
        <collision name='fr_1_collision'>
          <!-- <pose>-0.7875 -1.3657 0.15 0 -0 0</pose> -->
          <pose relative_to='fr_axle'>-0.05 0 0 0 1.5708 0</pose>
          <geometry>
            <!-- <mesh>
              <scale>0.00088 0.00088 0.00088</scale>
              <uri>model://zamboni/meshes/fr_1.stl</uri>
            </mesh> -->
            <cylinder>
              <radius>.28</radius>
              <length>.22</length>
            </cylinder>
          </geometry>
          <surface>
            <!-- <contact>
              <ode />
            </contact> -->
            <contact>
              <ode>
                <min_depth>0.001</min_depth>
                <kp>1e9</kp>
              </ode>
            </contact>
            <friction>
              <ode>
                <mu>0.9</mu>
                <mu2>0.9</mu2>
                <slip1>0.0</slip1>
                <slip2>0.0</slip2>
              </ode>
            </friction>
          </surface>
        </collision>
        <visual name='fr_1_visual'>
          <!-- <pose>-0.875 -1.5174 0 0 -0 0</pose> -->
          <pose>-0.770 -1.33 0.132 0 -0 0</pose>
          <geometry>
            <mesh>
              <scale>0.00088 0.00088 0.00088</scale>
              <uri>model://zamboni/meshes/fr_1.stl</uri>
            </mesh>
          </geometry>
        </visual>
        <self_collide>1</self_collide>
      </link>

      <link name='l_steer_1'>
        <pose relative_to='l_steer'>0 0 0 0 -0 0</pose>
        <!-- <inertial>
          <pose>0 0 0 0 -0 0</pose>
          <mass>1</mass>
          <inertia>
            <ixx>1</ixx>
            <ixy>0</ixy>
            <ixz>0</ixz>
            <iyy>1</iyy>
            <iyz>0</iyz>
            <izz>1</izz>
          </inertia>
        </inertial>
        <self_collide>1</self_collide> -->
      </link>

      <link name='r_steer_1'>
        <pose relative_to='r_steer'>0 0 0 0 -0 0</pose>
        <!-- <inertial>
          <pose>0 0 0 0 -0 0</pose>
          <mass>1</mass>
          <inertia>
            <ixx>1</ixx>
            <ixy>0</ixy>
            <ixz>0</ixz>
            <iyy>1</iyy>
            <iyz>0</iyz>
            <izz>1</izz>
          </inertia>
        </inertial>
        <self_collide>1</self_collide> -->
      </link>

      <link name="steering_wheel" />

      <joint name="steering_joint" type="revolute">
        <pose>-0.002 0 0 0 0 0</pose>
        <parent>chassis_link</parent>
        <child>steering_wheel</child>
        <axis>
          <xyz>-0.964118 0.000768 0.265556</xyz>
          <limit>
            <lower>-7.85</lower>
            <upper>7.85</upper>
          </limit>
          <dynamics>
            <damping>1.0</damping>
          </dynamics>
          <use_parent_model_frame>true</use_parent_model_frame>
        </axis>
        <physics>
          <ode>
            <cfm_damping>1</cfm_damping>
          </ode>
        </physics>
      </joint>

      <plugin name='ackermann_drive' filename='libgazebo_ros_ackermann_drive.so'>
        <ros>
          <namespace>zamboni</namespace>
          <remapping>cmd_vel:=cmd_vel</remapping>
          <remapping>odom:=odom</remapping>
          <remapping>distance:=distance</remapping>
        </ros>

        <update_rate>100.0</update_rate>

        <!-- wheels -->
        <front_left_joint>fl_axle</front_left_joint>
        <front_right_joint>fr_axle</front_right_joint>
        <rear_left_joint>bl_axle</rear_left_joint>
        <rear_right_joint>br_axle</rear_right_joint>
        <left_steering_joint>l_steer</left_steering_joint>
        <right_steering_joint>r_steer</right_steering_joint>
        <steering_wheel_joint>steering_joint</steering_wheel_joint>

        <!-- Max absolute steer angle for tyre in radians-->
        <!-- Any cmd_vel angular z greater than this would be capped -->
        <max_steer>0.6458</max_steer>

        <!-- Max absolute steering angle of steering wheel -->
        <!-- Max absolute steering angle of steering wheel -->
        <!-- <max_steering_angle>7.85</max_steering_angle> -->
        <max_steering_angle>7.85</max_steering_angle>


        <!-- Max absolute linear speed in m/s -->
        <max_speed>20</max_speed>

        <!-- PID tuning -->
        <left_steering_pid_gain>1500 0 1</left_steering_pid_gain>
        <left_steering_i_range>0 0</left_steering_i_range>
        <right_steering_pid_gain>1500 0 1</right_steering_pid_gain>
        <right_steering_i_range>0 0</right_steering_i_range>
        <linear_velocity_pid_gain>1000 0 1</linear_velocity_pid_gain>
        <linear_velocity_i_range>0 0</linear_velocity_i_range>

        <!-- output -->
        <publish_odom>true</publish_odom>
        <publish_odom_tf>true</publish_odom_tf>
        <publish_wheel_tf>true</publish_wheel_tf>
        <publish_distance>true</publish_distance>

        <odometry_frame>odom</odometry_frame>
        <robot_base_frame>base_link</robot_base_frame>

      </plugin>
    </model>
  </world>
</sdf>
