<?xml version="1.0" ?>
<!-- =================================================================================== -->
<!-- |    This document was autogenerated by xacro from ./src/Zamboni_Sim_ROS2/zamboni_description/urdf/zamboni.xacro | -->
<!-- |    EDITING THIS FILE BY HAND IS NOT RECOMMENDED                                 | -->
<!-- =================================================================================== -->
<robot name="zamboni">
  <!-- RVIZ MATERIAL COLOUR -->
  <material name="silver">
    <color rgba="0.1 0.1 0.1 0.5"/>
  </material>
  <material name="darkgrey">
    <color rgba="0 0 0 0.7"/>
  </material>
  <!-- ROBOT DEFINITION -->
  <link name="base_link"/>
  <joint name="chassis_link_joint" type="fixed">
    <origin rpy="0 0 0" xyz="0 0 0.325"/>
    <parent link="base_link"/>
    <child link="chassis_link"/>
  </joint>
  <joint name="realsense_joint" type="fixed">
    <axis xyz="0 1 0"/>
    <origin rpy="-1.5708 0 0" xyz="0 2.34 0.72"/>
    <parent link="chassis_link"/>
    <child link="realsense_link"/>
  </joint>
  <joint name="imu_joint" type="fixed">
    <axis xyz="0 1 0"/>
    <origin rpy="-1.5708 0 0" xyz="0 0 0.72"/>
    <parent link="chassis_link"/>
    <child link="imu_link"/>
  </joint>
  <link name="realsense_link">
    <collision>
      <origin rpy="0 0 0" xyz="0 0 0"/>
      <geometry>
        <box size="0.05 0.05 0.05"/>
      </geometry>
    </collision>
    <visual>
      <origin rpy="0 0 0" xyz="0 0 0"/>
      <geometry>
        <box size="0.05 0.05 0.05"/>
      </geometry>
    </visual>
    <inertial>
      <mass value="1e-5"/>
      <origin rpy="0 0 0" xyz="0 0 0"/>
      <inertia ixx="1e-6" ixy="0" ixz="0" iyy="1e-6" iyz="0" izz="1e-6"/>
    </inertial>
  </link>
  <material name="camera_aluminum">
    <color rgba="0.5 0.5 0.5 1"/>
  </material>
  <!-- camera body, with origin at bottom screw mount -->
  <joint name="camera_joint" type="fixed">
    <origin rpy="1.5708 -1.5708 0" xyz="0 0 0"/>
    <parent link="realsense_link"/>
    <child link="camera_bottom_screw_frame"/>
  </joint>
  <link name="camera_bottom_screw_frame"/>
  <joint name="camera_link_joint" type="fixed">
    <origin rpy="0 0 0" xyz="0 0.02 0.0115"/>
    <parent link="camera_bottom_screw_frame"/>
    <child link="camera_link"/>
  </joint>
  <link name="camera_link">
    <visual>
      <origin rpy="1.5707963267948966 0 1.5707963267948966" xyz="0.00987 -0.02 0"/>
      <geometry>
        <box size="0.099 0.023 0.02005"/>
        <!-- <mesh filename="package://realsense2_description/meshes/d415.stl" /> -->
      </geometry>
      <!-- <material name="${name}_aluminum"/> -->
    </visual>
    <collision>
      <origin rpy="0 0 0" xyz="0 -0.02 0"/>
      <geometry>
        <box size="0.02005 0.099 0.023"/>
      </geometry>
    </collision>
    <inertial>
      <!-- The following are not reliable values, and should not be used for modeling -->
      <mass value="0.564"/>
      <origin xyz="0 0 0"/>
      <inertia ixx="0.003881243" ixy="0.0" ixz="0.0" iyy="0.000498940" iyz="0.0" izz="0.003879257"/>
    </inertial>
  </link>
  <!-- camera depth joints and links -->
  <joint name="camera_depth_joint" type="fixed">
    <origin rpy="0 0 0" xyz="0 0 0"/>
    <parent link="camera_link"/>
    <child link="camera_depth_frame"/>
  </joint>
  <link name="camera_depth_frame"/>
  <joint name="camera_depth_optical_joint" type="fixed">
    <origin rpy="-1.5707963267948966 0 -1.5707963267948966" xyz="0 0 0"/>
    <parent link="camera_depth_frame"/>
    <child link="camera_depth_optical_frame"/>
  </joint>
  <link name="camera_depth_optical_frame"/>
  <!-- camera left IR joints and links -->
  <joint name="camera_left_ir_joint" type="fixed">
    <origin rpy="0 0 0" xyz="0 0.0 0"/>
    <parent link="camera_depth_frame"/>
    <child link="camera_left_ir_frame"/>
  </joint>
  <link name="camera_left_ir_frame"/>
  <joint name="camera_left_ir_optical_joint" type="fixed">
    <origin rpy="-1.5707963267948966 0 -1.5707963267948966" xyz="0 0 0"/>
    <parent link="camera_left_ir_frame"/>
    <child link="camera_left_ir_optical_frame"/>
  </joint>
  <link name="camera_left_ir_optical_frame"/>
  <!-- camera right IR joints and links -->
  <joint name="camera_right_ir_joint" type="fixed">
    <origin rpy="0 0 0" xyz="0 -0.055 0"/>
    <parent link="camera_depth_frame"/>
    <child link="camera_right_ir_frame"/>
  </joint>
  <link name="camera_right_ir_frame"/>
  <joint name="camera_right_ir_optical_joint" type="fixed">
    <origin rpy="-1.5707963267948966 0 -1.5707963267948966" xyz="0 0 0"/>
    <parent link="camera_right_ir_frame"/>
    <child link="camera_right_ir_optical_frame"/>
  </joint>
  <link name="camera_right_ir_optical_frame"/>
  <!-- camera color joints and links -->
  <joint name="camera_color_joint" type="fixed">
    <origin rpy="0 0 0" xyz="0 0.015 0"/>
    <parent link="camera_depth_frame"/>
    <child link="camera_color_frame"/>
  </joint>
  <link name="camera_color_frame"/>
  <joint name="camera_color_optical_joint" type="fixed">
    <origin rpy="-1.5707963267948966 0 -1.5707963267948966" xyz="0 0 0"/>
    <parent link="camera_color_frame"/>
    <child link="camera_color_optical_frame"/>
  </joint>
  <link name="camera_color_optical_frame"/>
  <link name="imu_link">
    <visual>
      <origin rpy="0 0 0" xyz="0 0 0"/>
      <geometry>
        <box size="0.05 0.05 0.05"/>
      </geometry>
    </visual>
    <inertial>
      <mass value="1e-5"/>
      <origin rpy="0 0 0" xyz="0 0 0"/>
      <inertia ixx="1e-6" ixy="0" ixz="0" iyy="1e-6" iyz="0" izz="1e-6"/>
    </inertial>
  </link>
  <link name="chassis_link">
    <inertial>
      <origin rpy="0 0 1.5708" xyz="0 0.73 0.30"/>
      <mass value="1580"/>
      <inertia ixx="1997.8579" ixy="-3e-05" ixz="-1e-06" iyy="442.7692" iyz="62.5206" izz="2238.0524"/>
    </inertial>
    <visual>
      <origin rpy="0 0 0" xyz="0 0 -0.4"/>
      <geometry>
        <mesh filename="package://zamboni_description/meshes/zamboni_no_cond.stl" scale="0.001 0.001 0.001"/>
      </geometry>
      <material name="silver"/>
    </visual>
    <collision>
      <origin rpy="0 0 0" xyz="0 0 0"/>
      <geometry>
        <mesh filename="package://zamboni_description/meshes/zamboni_no_cond.stl" scale="0.001 0.001 0.001"/>
      </geometry>
    </collision>
  </link>
  <joint name="br_axle" type="continuous">
    <origin rpy="0 0 0" xyz="0.69 0 0"/>
    <parent link="chassis_link"/>
    <child link="br_1"/>
    <axis xyz="-1.0 0.0 0.0"/>
  </joint>
  <link name="br_1">
    <inertial>
      <origin rpy="0 0 0" xyz="-0.05 0 0"/>
      <mass value="24.5"/>
      <inertia ixx="1.845139" ixy="-0.0" ixz="-0.0" iyy="1.049606" iyz="0.0" izz="1.049606"/>
    </inertial>
    <visual>
      <origin rpy="0 0 0" xyz="-0.8750 1.0136 0.15"/>
      <geometry>
        <mesh filename="package://zamboni_description/meshes/br_1.stl" scale="0.001 0.001 0.001"/>
      </geometry>
      <material name="darkgrey"/>
    </visual>
    <collision>
      <origin rpy="0 0 0" xyz="-0.8750 1.0136 0.15"/>
      <geometry>
        <mesh filename="package://zamboni_description/meshes/br_1.stl" scale="0.001 0.001 0.001"/>
      </geometry>
    </collision>
  </link>
  <joint name="bl_axle" type="continuous">
    <origin rpy="0 0 0" xyz="-0.69 0 0"/>
    <parent link="chassis_link"/>
    <child link="bl_1"/>
    <axis xyz="-1.0 0.0 0.0"/>
  </joint>
  <!-- Back left wheel -->
  <link name="bl_1">
    <inertial>
      <origin rpy="0 0 0" xyz="-0.05 0 0"/>
      <mass value="24.5"/>
      <inertia ixx="1.845139" ixy="-0.0" ixz="-0.0" iyy="1.049606" iyz="0.0" izz="1.049606"/>
    </inertial>
    <visual>
      <origin rpy="0 0 0" xyz="0.8750 1.0136 0.15"/>
      <geometry>
        <mesh filename="package://zamboni_description/meshes/bl_1.stl" scale="0.001 0.001 0.001"/>
      </geometry>
      <material name="darkgrey"/>
    </visual>
    <collision>
      <origin rpy="0 0 0" xyz="0.8750 1.0136 0.15"/>
      <geometry>
        <mesh filename="package://zamboni_description/meshes/bl_1.stl" scale="0.001 0.001 0.001"/>
      </geometry>
    </collision>
  </link>
  <!-- not sure TODO: add geometry -->
  <link name="r_steer_1">
    <inertial>
      <origin rpy="0 0 0" xyz="0.003381 0 0"/>
      <mass value="1"/>
      <inertia ixx="1.0" ixy="0.0" ixz="0.0" iyy="1.0" iyz="0.0" izz="1.0"/>
    </inertial>
  </link>
  <!-- not sure TODO: add geometry -->
  <link name="l_steer_1">
    <inertial>
      <origin rpy="0 0 0" xyz="0.003381 0 0"/>
      <mass value="1"/>
      <inertia ixx="1.0" ixy="0.0" ixz="0.0" iyy="1.0" iyz="0.0" izz="1.0"/>
    </inertial>
  </link>
  <!-- steering joint for ackermann -->
  <joint name="r_steer" type="revolute">
    <origin rpy="0 0 0" xyz="0.69 1.70 0"/>
    <parent link="chassis_link"/>
    <child link="r_steer_1"/>
    <axis xyz="0.0 0.0 1.0"/>
    <dynamics damping="0.01" friction="0.01"/>
    <limit effort="1000.0" lower="-0.95" upper="0.95" velocity="100"/>
  </joint>
  <!-- steering joint for ackermann -->
  <joint name="l_steer" type="revolute">
    <origin rpy="0 0 0" xyz="-0.69 1.70 0"/>
    <parent link="chassis_link"/>
    <child link="l_steer_1"/>
    <axis xyz="0.0 0.0 1.0"/>
    <dynamics damping="0.01" friction="0.01"/>
    <limit effort="1000.0" lower="-0.95" upper="0.95" velocity="100"/>
  </joint>
  <joint name="fr_axle" type="continuous">
    <origin rpy="0 0 0" xyz="0.05 0.0 0.0"/>
    <parent link="r_steer_1"/>
    <child link="fr_1"/>
    <axis xyz="-1.0 0.0 0.0"/>
  </joint>
  <!-- front right wheel -->
  <link name="fr_1">
    <inertial>
      <origin rpy="0 0 0" xyz="-0.0377 1.5929e-07 -1.5929e-07"/>
      <mass value="24.5"/>
      <inertia ixx="1.845139" ixy="-0.0" ixz="-0.0" iyy="1.049606" iyz="0.0" izz="1.049606"/>
    </inertial>
    <visual>
      <origin rpy="0 0 0" xyz="-0.8750 -1.5174 0.1444"/>
      <geometry>
        <mesh filename="package://zamboni_description/meshes/fr_1.stl" scale="0.001 0.001 0.001"/>
      </geometry>
      <material name="darkgrey"/>
    </visual>
    <collision>
      <origin rpy="0 0 0" xyz="-0.8750 -1.5174 0.1444"/>
      <geometry>
        <mesh filename="package://zamboni_description/meshes/fr_1.stl" scale="0.001 0.001 0.001"/>
      </geometry>
    </collision>
  </link>
  <joint name="fl_axle" type="continuous">
    <origin rpy="0 0 0" xyz="-0.05 0.0 0.0"/>
    <parent link="l_steer_1"/>
    <child link="fl_1"/>
    <axis xyz="-1.0 0.0 0.0"/>
  </joint>
  <!-- front left wheel -->
  <link name="fl_1">
    <inertial>
      <origin rpy="0 0 0" xyz="-0.0377 0 0"/>
      <mass value="24.5"/>
      <inertia ixx="1.845139" ixy="-0.0" ixz="-0.0" iyy="1.049606" iyz="0.0" izz="1.049606"/>
    </inertial>
    <visual>
      <origin rpy="0 0 0" xyz="0.8750 -1.5174 0.1444"/>
      <geometry>
        <mesh filename="package://zamboni_description/meshes/fl_1.stl" scale="0.001 0.001 0.001"/>
      </geometry>
      <material name="darkgrey"/>
    </visual>
    <collision>
      <origin rpy="0 0 0" xyz="0.8750 -1.5174 0.1444"/>
      <geometry>
        <mesh filename="package://zamboni_description/meshes/fl_1.stl" scale="0.001 0.001 0.001"/>
      </geometry>
    </collision>
  </link>
  <gazebo reference="chassis_link">
    <material>Gazebo/Blue</material>
    <mu1>0.2</mu1>
    <mu2>0.2</mu2>
    <selfCollide>true</selfCollide>
    <gravity>true</gravity>
  </gazebo>
  <gazebo reference="br_1">
    <material>Gazebo/DarkGrey</material>
    <mu1>1.7</mu1>
    <mu2>1.7</mu2>
    <selfCollide>true</selfCollide>
  </gazebo>
  <gazebo reference="bl_1">
    <material>Gazebo/DarkGrey</material>
    <mu1>1.7</mu1>
    <mu2>1.7</mu2>
    <selfCollide>true</selfCollide>
  </gazebo>
  <gazebo reference="fr_1">
    <material>Gazebo/DarkGrey</material>
    <mu1>1.7</mu1>
    <mu2>1.7</mu2>
    <selfCollide>true</selfCollide>
  </gazebo>
  <gazebo reference="fl_1">
    <material>Gazebo/DarkGrey</material>
    <mu1>1.1</mu1>
    <mu2>1.1</mu2>
    <selfCollide>true</selfCollide>
  </gazebo>
  <gazebo reference="r_steer_1">
    <material>Gazebo/DarkGrey</material>
    <mu1>0.2</mu1>
    <mu2>0.2</mu2>
    <selfCollide>true</selfCollide>
  </gazebo>
  <gazebo reference="l_steer_1">
    <material>Gazebo/DarkGrey</material>
    <mu1>0.2</mu1>
    <mu2>0.2</mu2>
    <selfCollide>true</selfCollide>
  </gazebo>
</robot>
